Workbook

Sheet Test_Cases
A1: VPAP 4.1 Policy Engine - 20 Synthetic Test Cases
A2: All records are synthetic test fixtures. CVE-shaped IDs, assets, timestamps, and evidence values are designed to resemble production data without containing real organizational data.
A4: Test_Case_ID | B4: Record_Type | C4: Finding_Instance_ID | D4: Source_System | E4: Source_Finding_ID | F4: CVE_ID | G4: Asset_ID | H4: Asset_Name | I4: Package | J4: Installed_Version | K4: CVSS_Base_Score | L4: Description | M4: EPSS_Probability | N4: EPSS_Status | O4: EPSS_Percentile | P4: KEV_Value | Q4: KEV_Status | R4: Internet_Exposure | S4: Internet_Status | T4: Runtime_Applicability | U4: Runtime_Status | V4: Attack_Path_Reachable | W4: Attack_Path_Status | X4: Business_Criticality | Y4: Business_Status | Z4: Compensating_Controls | AA4: Internal_Active_Exploitation | AB4: Evidence_Sources | AC4: Retrieved_At | AD4: Evidence_Confidence | AE4: Evidence_Snapshot_ID | AF4: Policy_Version | AG4: Quality_Check | AH4: Mandatory_Remediation | AI4: Exploitation_Points | AJ4: Exposure_Points | AK4: Technical_Impact_Points | AL4: Business_Impact_Points | AM4: VPS | AN4: Expected_Priority | AO4: Expected_Decision_Status | AP4: Expected_Confidence | AQ4: Expected_Ticket_Action | AR4: Expected_Rules_Applied | AS4: Scenario_Notes
A5: SYN-001 | B5: SYNTHETIC_TEST_CASE | C5: finding-8f31a2 | D5: WIZ | E5: wiz-finding-001 | F5: CVE-2026-99001 | G5: asset-payments-api-prod-01 | H5: Production payment API server | I5: log4j-core | J5: 2.14.1 | K5: 10 | L5: Remote code execution in application logging path | M5: 0.99999 | N5: KNOWN | O5: 1 | P5: TRUE | Q5: KNOWN | R5: TRUE | S5: KNOWN | T5: TRUE | U5: KNOWN | V5: TRUE | W5: KNOWN | X5: CRITICAL | Y5: KNOWN | Z5: WAF blocks JNDI patterns; LDAP egress restricted | AA5: FALSE | AB5: WIZ;CMDB;FIRST_EPSS;CISA_KEV | AC5: 46243.427 | AD5: HIGH | AE5: snapshot-20260809-000145 | AF5: 2026.07-pilot.1 | AG5: =IF(OR(N5<>"KNOWN",Q5<>"KNOWN",S5<>"KNOWN",U5<>"KNOWN",W5<>"KNOWN",Y5<>"KNOWN"),"NEEDS_REVIEW","OK") -> OK | AH5: =IF(OR(AND(Q5="KNOWN",P5=TRUE),AA5=TRUE),TRUE,FALSE) -> TRUE | AI5: =IF(AG5<>"OK",0,IF(AH5=TRUE,Policy_Config!$B$11,IF(M5>=Policy_Config!$C$12,Policy_Config!$B$12,IF(M5>=Policy_Config!$C$13,Policy_Config!$B$13,IF(M5>=Policy_Config!$C$14,Policy_Config!$B$14,Policy_Config!$B$15))))) -> 30 | AJ5: =IF(AG5<>"OK",0,IF(AND(R5=TRUE,V5=TRUE),Policy_Config!$B$17,IF(OR(R5=TRUE,V5=TRUE),Policy_Config!$B$18,Policy_Config!$B$19))) -> 20 | AK5: =IF(AG5<>"OK",0,IF(T5=FALSE,Policy_Config!$B$21,IF(K5>=Policy_Config!$C$22,Policy_Config!$B$22,IF(K5>=Policy_Config!$C$23,Policy_Config!$B$23,Policy_Config!$B$24)))) -> 20 | AL5: =IF(AG5<>"OK",0,IF(X5="CRITICAL",Policy_Config!$B$26,IF(X5="HIGH",Policy_Config!$B$27,IF(X5="MEDIUM",Policy_Config!$B$28,Policy_Config!$B$29)))) -> 15 | AM5: =IF(AG5<>"OK","",SUM(AI5:AL5)) -> 85 | AN5: =IF(AG5<>"OK","REVIEW",IF(AM5>=Policy_Config!$B$5,"P0",IF(AM5>=Policy_Config!$B$6,"P1",IF(AM5>=Policy_Config!$B$7,"P2","P3")))) -> P0 | AO5: =IF(AG5<>"OK","NEEDS_REVIEW","FINAL") -> FINAL | AP5: =IF(AG5<>"OK","LOW","HIGH") -> HIGH | AQ5: =IF(OR(AN5="P0",AN5="P1",AH5=TRUE),"UPSERT_TICKET",IF(AO5="NEEDS_REVIEW","REVIEW_QUEUE","NO_IMMEDIATE_TICKET")) -> UPSERT_TICKET | AR5: SSVC.EXPLOITATION.ACTIVE | SSVC.AUTOMATABLE.YES | SSVC.TECHNICAL_IMPACT.HIGH | SSVC.BUSINESS_IMPACT.HIGH | VPS.THRESHOLD.P0 | AS5: High-confidence P0 KEV scenario.
A6: SYN-002 | B6: SYNTHETIC_TEST_CASE | C6: finding-8f31a3 | D6: WIZ | E6: wiz-finding-002 | F6: CVE-2026-99002 | G6: asset-customer-portal-prod-02 | H6: Customer portal web tier | I6: apache-tomcat | J6: 9.0.82 | K6: 9.1 | L6: Authentication bypass in public web service | M6: 0.91 | N6: KNOWN | O6: 0.995 | P6: TRUE | Q6: KNOWN | R6: TRUE | S6: KNOWN | T6: TRUE | U6: KNOWN | V6: TRUE | W6: KNOWN | X6: HIGH | Y6: KNOWN | Z6: Managed WAF; rate limiting | AA6: FALSE | AB6: WIZ;CMDB;FIRST_EPSS;CISA_KEV | AC6: 46243.428 | AD6: HIGH | AE6: snapshot-20260809-000146 | AF6: 2026.07-pilot.1 | AG6: =IF(OR(N6<>"KNOWN",Q6<>"KNOWN",S6<>"KNOWN",U6<>"KNOWN",W6<>"KNOWN",Y6<>"KNOWN"),"NEEDS_REVIEW","OK") -> OK | AH6: =IF(OR(AND(Q6="KNOWN",P6=TRUE),AA6=TRUE),TRUE,FALSE) -> TRUE | AI6: =IF(AG6<>"OK",0,IF(AH6=TRUE,Policy_Config!$B$11,IF(M6>=Policy_Config!$C$12,Policy_Config!$B$12,IF(M6>=Policy_Config!$C$13,Policy_Config!$B$13,IF(M6>=Policy_Config!$C$14,Policy_Config!$B$14,Policy_Config!$B$15))))) -> 30 | AJ6: =IF(AG6<>"OK",0,IF(AND(R6=TRUE,V6=TRUE),Policy_Config!$B$17,IF(OR(R6=TRUE,V6=TRUE),Policy_Config!$B$18,Policy_Config!$B$19))) -> 20 | AK6: =IF(AG6<>"OK",0,IF(T6=FALSE,Policy_Config!$B$21,IF(K6>=Policy_Config!$C$22,Policy_Config!$B$22,IF(K6>=Policy_Config!$C$23,Policy_Config!$B$23,Policy_Config!$B$24)))) -> 20 | AL6: =IF(AG6<>"OK",0,IF(X6="CRITICAL",Policy_Config!$B$26,IF(X6="HIGH",Policy_Config!$B$27,IF(X6="MEDIUM",Policy_Config!$B$28,Policy_Config!$B$29)))) -> 10 | AM6: =IF(AG6<>"OK","",SUM(AI6:AL6)) -> 80 | AN6: =IF(AG6<>"OK","REVIEW",IF(AM6>=Policy_Config!$B$5,"P0",IF(AM6>=Policy_Config!$B$6,"P1",IF(AM6>=Policy_Config!$B$7,"P2","P3")))) -> P0 | AO6: =IF(AG6<>"OK","NEEDS_REVIEW","FINAL") -> FINAL | AP6: =IF(AG6<>"OK","LOW","HIGH") -> HIGH | AQ6: =IF(OR(AN6="P0",AN6="P1",AH6=TRUE),"UPSERT_TICKET",IF(AO6="NEEDS_REVIEW","REVIEW_QUEUE","NO_IMMEDIATE_TICKET")) -> UPSERT_TICKET | AR6: SSVC.EXPLOITATION.ACTIVE | SSVC.AUTOMATABLE.YES | SSVC.TECHNICAL_IMPACT.HIGH | VPS.THRESHOLD.P0 | AS6: KEV and internet-facing application.
A7: SYN-003 | B7: SYNTHETIC_TEST_CASE | C7: finding-8f31a4 | D7: WIZ | E7: wiz-finding-003 | F7: CVE-2026-99003 | G7: asset-ledger-worker-prod-01 | H7: Internal ledger processing worker | I7: openssl | J7: 3.0.8 | K7: 9.8 | L7: Remote code execution in internal processing component | M7: 0.87 | N7: KNOWN | O7: 0.985 | P7: FALSE | Q7: KNOWN | R7: FALSE | S7: KNOWN | T7: TRUE | U7: KNOWN | V7: TRUE | W7: KNOWN | X7: CRITICAL | Y7: KNOWN | Z7: Private subnet; egress allowlist | AA7: FALSE | AB7: WIZ;CMDB;FIRST_EPSS;CISA_KEV | AC7: 46243.43 | AD7: HIGH | AE7: snapshot-20260809-000147 | AF7: 2026.07-pilot.1 | AG7: =IF(OR(N7<>"KNOWN",Q7<>"KNOWN",S7<>"KNOWN",U7<>"KNOWN",W7<>"KNOWN",Y7<>"KNOWN"),"NEEDS_REVIEW","OK") -> OK | AH7: =IF(OR(AND(Q7="KNOWN",P7=TRUE),AA7=TRUE),TRUE,FALSE) -> FALSE | AI7: =IF(AG7<>"OK",0,IF(AH7=TRUE,Policy_Config!$B$11,IF(M7>=Policy_Config!$C$12,Policy_Config!$B$12,IF(M7>=Policy_Config!$C$13,Policy_Config!$B$13,IF(M7>=Policy_Config!$C$14,Policy_Config!$B$14,Policy_Config!$B$15))))) -> 20 | AJ7: =IF(AG7<>"OK",0,IF(AND(R7=TRUE,V7=TRUE),Policy_Config!$B$17,IF(OR(R7=TRUE,V7=TRUE),Policy_Config!$B$18,Policy_Config!$B$19))) -> 10 | AK7: =IF(AG7<>"OK",0,IF(T7=FALSE,Policy_Config!$B$21,IF(K7>=Policy_Config!$C$22,Policy_Config!$B$22,IF(K7>=Policy_Config!$C$23,Policy_Config!$B$23,Policy_Config!$B$24)))) -> 20 | AL7: =IF(AG7<>"OK",0,IF(X7="CRITICAL",Policy_Config!$B$26,IF(X7="HIGH",Policy_Config!$B$27,IF(X7="MEDIUM",Policy_Config!$B$28,Policy_Config!$B$29)))) -> 15 | AM7: =IF(AG7<>"OK","",SUM(AI7:AL7)) -> 65 | AN7: =IF(AG7<>"OK","REVIEW",IF(AM7>=Policy_Config!$B$5,"P0",IF(AM7>=Policy_Config!$B$6,"P1",IF(AM7>=Policy_Config!$B$7,"P2","P3")))) -> P1 | AO7: =IF(AG7<>"OK","NEEDS_REVIEW","FINAL") -> FINAL | AP7: =IF(AG7<>"OK","LOW","HIGH") -> HIGH | AQ7: =IF(OR(AN7="P0",AN7="P1",AH7=TRUE),"UPSERT_TICKET",IF(AO7="NEEDS_REVIEW","REVIEW_QUEUE","NO_IMMEDIATE_TICKET")) -> UPSERT_TICKET | AR7: SSVC.EXPLOITATION.ELEVATED | SSVC.ATTACK_PATH.REACHABLE | SSVC.BUSINESS_IMPACT.HIGH | VPS.THRESHOLD.P1 | AS7: Internal but reachable through approved service path.
A8: SYN-004 | B8: SYNTHETIC_TEST_CASE | C8: finding-8f31a5 | D8: WIZ | E8: wiz-finding-004 | F8: CVE-2026-99004 | G8: asset-edge-proxy-prod-01 | H8: Internet edge reverse proxy | I8: nginx | J8: 1.24.0 | K8: 8.8 | L8: HTTP/2 denial-of-service condition | M8: 0.65 | N8: KNOWN | O8: 0.965 | P8: FALSE | Q8: KNOWN | R8: TRUE | S8: KNOWN | T8: TRUE | U8: KNOWN | V8: TRUE | W8: KNOWN | X8: HIGH | Y8: KNOWN | Z8: Connection limits; autoscaling | AA8: FALSE | AB8: WIZ;CMDB;FIRST_EPSS;CISA_KEV | AC8: 46243.431 | AD8: HIGH | AE8: snapshot-20260809-000148 | AF8: 2026.07-pilot.1 | AG8: =IF(OR(N8<>"KNOWN",Q8<>"KNOWN",S8<>"KNOWN",U8<>"KNOWN",W8<>"KNOWN",Y8<>"KNOWN"),"NEEDS_REVIEW","OK") -> OK | AH8: =IF(OR(AND(Q8="KNOWN",P8=TRUE),AA8=TRUE),TRUE,FALSE) -> FALSE | AI8: =IF(AG8<>"OK",0,IF(AH8=TRUE,Policy_Config!$B$11,IF(M8>=Policy_Config!$C$12,Policy_Config!$B$12,IF(M8>=Policy_Config!$C$13,Policy_Config!$B$13,IF(M8>=Policy_Config!$C$14,Policy_Config!$B$14,Policy_Config!$B$15))))) -> 15 | AJ8: =IF(AG8<>"OK",0,IF(AND(R8=TRUE,V8=TRUE),Policy_Config!$B$17,IF(OR(R8=TRUE,V8=TRUE),Policy_Config!$B$18,Policy_Config!$B$19))) -> 20 | AK8: =IF(AG8<>"OK",0,IF(T8=FALSE,Policy_Config!$B$21,IF(K8>=Policy_Config!$C$22,Policy_Config!$B$22,IF(K8>=Policy_Config!$C$23,Policy_Config!$B$23,Policy_Config!$B$24)))) -> 15 | AL8: =IF(AG8<>"OK",0,IF(X8="CRITICAL",Policy_Config!$B$26,IF(X8="HIGH",Policy_Config!$B$27,IF(X8="MEDIUM",Policy_Config!$B$28,Policy_Config!$B$29)))) -> 10 | AM8: =IF(AG8<>"OK","",SUM(AI8:AL8)) -> 60 | AN8: =IF(AG8<>"OK","REVIEW",IF(AM8>=Policy_Config!$B$5,"P0",IF(AM8>=Policy_Config!$B$6,"P1",IF(AM8>=Policy_Config!$B$7,"P2","P3")))) -> P1 | AO8: =IF(AG8<>"OK","NEEDS_REVIEW","FINAL") -> FINAL | AP8: =IF(AG8<>"OK","LOW","HIGH") -> HIGH | AQ8: =IF(OR(AN8="P0",AN8="P1",AH8=TRUE),"UPSERT_TICKET",IF(AO8="NEEDS_REVIEW","REVIEW_QUEUE","NO_IMMEDIATE_TICKET")) -> UPSERT_TICKET | AR8: SSVC.EXPLOITATION.ELEVATED | SSVC.AUTOMATABLE.YES | SSVC.BUSINESS_IMPACT.HIGH | VPS.THRESHOLD.P1 | AS8: Publicly reachable, high business service impact.
A9: SYN-005 | B9: SYNTHETIC_TEST_CASE | C9: finding-8f31a6 | D9: WIZ | E9: wiz-finding-005 | F9: CVE-2026-99005 | G9: asset-remote-access-prod-01 | H9: Remote access VPN gateway | I9: vpn-gateway | J9: 8.4.2 | K9: 9.8 | L9: Command injection through VPN administration endpoint | M9: 0.76 | N9: KNOWN | O9: 0.978 | P9: TRUE | Q9: KNOWN | R9: TRUE | S9: KNOWN | T9: TRUE | U9: KNOWN | V9: TRUE | W9: KNOWN | X9: CRITICAL | Y9: KNOWN | Z9: MFA; management interface restricted | AA9: FALSE | AB9: WIZ;CMDB;FIRST_EPSS;CISA_KEV | AC9: 46243.433 | AD9: HIGH | AE9: snapshot-20260809-000149 | AF9: 2026.07-pilot.1 | AG9: =IF(OR(N9<>"KNOWN",Q9<>"KNOWN",S9<>"KNOWN",U9<>"KNOWN",W9<>"KNOWN",Y9<>"KNOWN"),"NEEDS_REVIEW","OK") -> OK | AH9: =IF(OR(AND(Q9="KNOWN",P9=TRUE),AA9=TRUE),TRUE,FALSE) -> TRUE | AI9: =IF(AG9<>"OK",0,IF(AH9=TRUE,Policy_Config!$B$11,IF(M9>=Policy_Config!$C$12,Policy_Config!$B$12,IF(M9>=Policy_Config!$C$13,Policy_Config!$B$13,IF(M9>=Policy_Config!$C$14,Policy_Config!$B$14,Policy_Config!$B$15))))) -> 30 | AJ9: =IF(AG9<>"OK",0,IF(AND(R9=TRUE,V9=TRUE),Policy_Config!$B$17,IF(OR(R9=TRUE,V9=TRUE),Policy_Config!$B$18,Policy_Config!$B$19))) -> 20 | AK9: =IF(AG9<>"OK",0,IF(T9=FALSE,Policy_Config!$B$21,IF(K9>=Policy_Config!$C$22,Policy_Config!$B$22,IF(K9>=Policy_Config!$C$23,Policy_Config!$B$23,Policy_Config!$B$24)))) -> 20 | AL9: =IF(AG9<>"OK",0,IF(X9="CRITICAL",Policy_Config!$B$26,IF(X9="HIGH",Policy_Config!$B$27,IF(X9="MEDIUM",Policy_Config!$B$28,Policy_Config!$B$29)))) -> 15 | AM9: =IF(AG9<>"OK","",SUM(AI9:AL9)) -> 85 | AN9: =IF(AG9<>"OK","REVIEW",IF(AM9>=Policy_Config!$B$5,"P0",IF(AM9>=Policy_Config!$B$6,"P1",IF(AM9>=Policy_Config!$B$7,"P2","P3")))) -> P0 | AO9: =IF(AG9<>"OK","NEEDS_REVIEW","FINAL") -> FINAL | AP9: =IF(AG9<>"OK","LOW","HIGH") -> HIGH | AQ9: =IF(OR(AN9="P0",AN9="P1",AH9=TRUE),"UPSERT_TICKET",IF(AO9="NEEDS_REVIEW","REVIEW_QUEUE","NO_IMMEDIATE_TICKET")) -> UPSERT_TICKET | AR9: SSVC.EXPLOITATION.ACTIVE | SSVC.AUTOMATABLE.YES | SSVC.TECHNICAL_IMPACT.HIGH | VPS.THRESHOLD.P0 | AS9: Confirmed exploitation with high-value perimeter access.
A10: SYN-006 | B10: SYNTHETIC_TEST_CASE | C10: finding-8f31a7 | D10: WIZ | E10: wiz-finding-006 | F10: CVE-2026-99006 | G10: asset-reporting-db-prod-01 | H10: Reporting database cluster | I10: postgresql-extension | J10: 15.3 | K10: 7.5 | L10: Privilege escalation through database extension | M10: 0.31 | N10: KNOWN | O10: 0.89 | P10: FALSE | Q10: KNOWN | R10: FALSE | S10: KNOWN | T10: TRUE | U10: KNOWN | V10: FALSE | W10: KNOWN | X10: HIGH | Y10: KNOWN | Z10: Database role separation; private subnet | AA10: FALSE | AB10: WIZ;CMDB;FIRST_EPSS;CISA_KEV | AC10: 46243.434 | AD10: HIGH | AE10: snapshot-20260809-000150 | AF10: 2026.07-pilot.1 | AG10: =IF(OR(N10<>"KNOWN",Q10<>"KNOWN",S10<>"KNOWN",U10<>"KNOWN",W10<>"KNOWN",Y10<>"KNOWN"),"NEEDS_REVIEW","OK") -> OK | AH10: =IF(OR(AND(Q10="KNOWN",P10=TRUE),AA10=TRUE),TRUE,FALSE) -> FALSE | AI10: =IF(AG10<>"OK",0,IF(AH10=TRUE,Policy_Config!$B$11,IF(M10>=Policy_Config!$C$12,Policy_Config!$B$12,IF(M10>=Policy_Config!$C$13,Policy_Config!$B$13,IF(M10>=Policy_Config!$C$14,Policy_Config!$B$14,Policy_Config!$B$15))))) -> 15 | AJ10: =IF(AG10<>"OK",0,IF(AND(R10=TRUE,V10=TRUE),Policy_Config!$B$17,IF(OR(R10=TRUE,V10=TRUE),Policy_Config!$B$18,Policy_Config!$B$19))) -> 0 | AK10: =IF(AG10<>"OK",0,IF(T10=FALSE,Policy_Config!$B$21,IF(K10>=Policy_Config!$C$22,Policy_Config!$B$22,IF(K10>=Policy_Config!$C$23,Policy_Config!$B$23,Policy_Config!$B$24)))) -> 15 | AL10: =IF(AG10<>"OK",0,IF(X10="CRITICAL",Policy_Config!$B$26,IF(X10="HIGH",Policy_Config!$B$27,IF(X10="MEDIUM",Policy_Config!$B$28,Policy_Config!$B$29)))) -> 10 | AM10: =IF(AG10<>"OK","",SUM(AI10:AL10)) -> 40 | AN10: =IF(AG10<>"OK","REVIEW",IF(AM10>=Policy_Config!$B$5,"P0",IF(AM10>=Policy_Config!$B$6,"P1",IF(AM10>=Policy_Config!$B$7,"P2","P3")))) -> P2 | AO10: =IF(AG10<>"OK","NEEDS_REVIEW","FINAL") -> FINAL | AP10: =IF(AG10<>"OK","LOW","HIGH") -> HIGH | AQ10: =IF(OR(AN10="P0",AN10="P1",AH10=TRUE),"UPSERT_TICKET",IF(AO10="NEEDS_REVIEW","REVIEW_QUEUE","NO_IMMEDIATE_TICKET")) -> NO_IMMEDIATE_TICKET | AR10: SSVC.EXPLOITATION.MODERATE | SSVC.ATTACK_PATH.NOT_REACHABLE | VPS.THRESHOLD.P2 | AS10: No reachable attack path currently confirmed.
A11: SYN-007 | B11: SYNTHETIC_TEST_CASE | C11: finding-8f31a8 | D11: WIZ | E11: wiz-finding-007 | F11: CVE-2026-99007 | G11: asset-ci-jenkins-prod-01 | H11: CI/CD Jenkins controller | I11: jenkins-core | J11: 2.401.3 | K11: 8 | L11: Authentication weakness in build administration endpoint | M11: 0.22 | N11: KNOWN | O11: 0.78 | P11: FALSE | Q11: KNOWN | R11: TRUE | S11: KNOWN | T11: TRUE | U11: KNOWN | V11: TRUE | W11: KNOWN | X11: MEDIUM | Y11: KNOWN | Z11: SSO; IP allowlist; build isolation | AA11: FALSE | AB11: WIZ;CMDB;FIRST_EPSS;CISA_KEV | AC11: 46243.435 | AD11: HIGH | AE11: snapshot-20260809-000151 | AF11: 2026.07-pilot.1 | AG11: =IF(OR(N11<>"KNOWN",Q11<>"KNOWN",S11<>"KNOWN",U11<>"KNOWN",W11<>"KNOWN",Y11<>"KNOWN"),"NEEDS_REVIEW","OK") -> OK | AH11: =IF(OR(AND(Q11="KNOWN",P11=TRUE),AA11=TRUE),TRUE,FALSE) -> FALSE | AI11: =IF(AG11<>"OK",0,IF(AH11=TRUE,Policy_Config!$B$11,IF(M11>=Policy_Config!$C$12,Policy_Config!$B$12,IF(M11>=Policy_Config!$C$13,Policy_Config!$B$13,IF(M11>=Policy_Config!$C$14,Policy_Config!$B$14,Policy_Config!$B$15))))) -> 10 | AJ11: =IF(AG11<>"OK",0,IF(AND(R11=TRUE,V11=TRUE),Policy_Config!$B$17,IF(OR(R11=TRUE,V11=TRUE),Policy_Config!$B$18,Policy_Config!$B$19))) -> 20 | AK11: =IF(AG11<>"OK",0,IF(T11=FALSE,Policy_Config!$B$21,IF(K11>=Policy_Config!$C$22,Policy_Config!$B$22,IF(K11>=Policy_Config!$C$23,Policy_Config!$B$23,Policy_Config!$B$24)))) -> 15 | AL11: =IF(AG11<>"OK",0,IF(X11="CRITICAL",Policy_Config!$B$26,IF(X11="HIGH",Policy_Config!$B$27,IF(X11="MEDIUM",Policy_Config!$B$28,Policy_Config!$B$29)))) -> 5 | AM11: =IF(AG11<>"OK","",SUM(AI11:AL11)) -> 50 | AN11: =IF(AG11<>"OK","REVIEW",IF(AM11>=Policy_Config!$B$5,"P0",IF(AM11>=Policy_Config!$B$6,"P1",IF(AM11>=Policy_Config!$B$7,"P2","P3")))) -> P2 | AO11: =IF(AG11<>"OK","NEEDS_REVIEW","FINAL") -> FINAL | AP11: =IF(AG11<>"OK","LOW","HIGH") -> HIGH | AQ11: =IF(OR(AN11="P0",AN11="P1",AH11=TRUE),"UPSERT_TICKET",IF(AO11="NEEDS_REVIEW","REVIEW_QUEUE","NO_IMMEDIATE_TICKET")) -> NO_IMMEDIATE_TICKET | AR11: SSVC.EXPLOITATION.LOW | SSVC.AUTOMATABLE.YES | SSVC.BUSINESS_IMPACT.MEDIUM | VPS.THRESHOLD.P2 | AS11: Internet reachable but protected by an IP allowlist.
A12: SYN-008 | B12: SYNTHETIC_TEST_CASE | C12: finding-8f31a9 | D12: WIZ | E12: wiz-finding-008 | F12: CVE-2026-99008 | G12: asset-batch-worker-prod-03 | H12: Batch processing worker | I12: linux-kernel | J12: 5.15.0 | K12: 7.8 | L12: Local privilege escalation in kernel subsystem | M12: 0.18 | N12: KNOWN | O12: 0.71 | P12: FALSE | Q12: KNOWN | R12: FALSE | S12: KNOWN | T12: TRUE | U12: KNOWN | V12: FALSE | W12: KNOWN | X12: HIGH | Y12: KNOWN | Z12: Non-root container; host hardening | AA12: FALSE | AB12: WIZ;CMDB;FIRST_EPSS;CISA_KEV | AC12: 46243.437 | AD12: HIGH | AE12: snapshot-20260809-000152 | AF12: 2026.07-pilot.1 | AG12: =IF(OR(N12<>"KNOWN",Q12<>"KNOWN",S12<>"KNOWN",U12<>"KNOWN",W12<>"KNOWN",Y12<>"KNOWN"),"NEEDS_REVIEW","OK") -> OK | AH12: =IF(OR(AND(Q12="KNOWN",P12=TRUE),AA12=TRUE),TRUE,FALSE) -> FALSE | AI12: =IF(AG12<>"OK",0,IF(AH12=TRUE,Policy_Config!$B$11,IF(M12>=Policy_Config!$C$12,Policy_Config!$B$12,IF(M12>=Policy_Config!$C$13,Policy_Config!$B$13,IF(M12>=Policy_Config!$C$14,Policy_Config!$B$14,Policy_Config!$B$15))))) -> 10 | AJ12: =IF(AG12<>"OK",0,IF(AND(R12=TRUE,V12=TRUE),Policy_Config!$B$17,IF(OR(R12=TRUE,V12=TRUE),Policy_Config!$B$18,Policy_Config!$B$19))) -> 0 | AK12: =IF(AG12<>"OK",0,IF(T12=FALSE,Policy_Config!$B$21,IF(K12>=Policy_Config!$C$22,Policy_Config!$B$22,IF(K12>=Policy_Config!$C$23,Policy_Config!$B$23,Policy_Config!$B$24)))) -> 15 | AL12: =IF(AG12<>"OK",0,IF(X12="CRITICAL",Policy_Config!$B$26,IF(X12="HIGH",Policy_Config!$B$27,IF(X12="MEDIUM",Policy_Config!$B$28,Policy_Config!$B$29)))) -> 10 | AM12: =IF(AG12<>"OK","",SUM(AI12:AL12)) -> 35 | AN12: =IF(AG12<>"OK","REVIEW",IF(AM12>=Policy_Config!$B$5,"P0",IF(AM12>=Policy_Config!$B$6,"P1",IF(AM12>=Policy_Config!$B$7,"P2","P3")))) -> P2 | AO12: =IF(AG12<>"OK","NEEDS_REVIEW","FINAL") -> FINAL | AP12: =IF(AG12<>"OK","LOW","HIGH") -> HIGH | AQ12: =IF(OR(AN12="P0",AN12="P1",AH12=TRUE),"UPSERT_TICKET",IF(AO12="NEEDS_REVIEW","REVIEW_QUEUE","NO_IMMEDIATE_TICKET")) -> NO_IMMEDIATE_TICKET | AR12: SSVC.EXPLOITATION.LOW | SSVC.ATTACK_PATH.NOT_REACHABLE | VPS.THRESHOLD.P2 | AS12: Requires local access; no external route identified.
A13: SYN-009 | B13: SYNTHETIC_TEST_CASE | C13: finding-8f31aa | D13: WIZ | E13: wiz-finding-009 | F13: CVE-2026-99009 | G13: asset-observability-prod-01 | H13: Observability dashboard | I13: grafana | J13: 10.1.5 | K13: 8.1 | L13: Authentication bypass in dashboard service | M13: 0.54 | N13: KNOWN | O13: 0.94 | P13: FALSE | Q13: KNOWN | R13: TRUE | S13: KNOWN | T13: TRUE | U13: KNOWN | V13: TRUE | W13: KNOWN | X13: HIGH | Y13: KNOWN | Z13: SSO; read-only default role | AA13: FALSE | AB13: WIZ;CMDB;FIRST_EPSS;CISA_KEV | AC13: 46243.438 | AD13: HIGH | AE13: snapshot-20260809-000153 | AF13: 2026.07-pilot.1 | AG13: =IF(OR(N13<>"KNOWN",Q13<>"KNOWN",S13<>"KNOWN",U13<>"KNOWN",W13<>"KNOWN",Y13<>"KNOWN"),"NEEDS_REVIEW","OK") -> OK | AH13: =IF(OR(AND(Q13="KNOWN",P13=TRUE),AA13=TRUE),TRUE,FALSE) -> FALSE | AI13: =IF(AG13<>"OK",0,IF(AH13=TRUE,Policy_Config!$B$11,IF(M13>=Policy_Config!$C$12,Policy_Config!$B$12,IF(M13>=Policy_Config!$C$13,Policy_Config!$B$13,IF(M13>=Policy_Config!$C$14,Policy_Config!$B$14,Policy_Config!$B$15))))) -> 15 | AJ13: =IF(AG13<>"OK",0,IF(AND(R13=TRUE,V13=TRUE),Policy_Config!$B$17,IF(OR(R13=TRUE,V13=TRUE),Policy_Config!$B$18,Policy_Config!$B$19))) -> 20 | AK13: =IF(AG13<>"OK",0,IF(T13=FALSE,Policy_Config!$B$21,IF(K13>=Policy_Config!$C$22,Policy_Config!$B$22,IF(K13>=Policy_Config!$C$23,Policy_Config!$B$23,Policy_Config!$B$24)))) -> 15 | AL13: =IF(AG13<>"OK",0,IF(X13="CRITICAL",Policy_Config!$B$26,IF(X13="HIGH",Policy_Config!$B$27,IF(X13="MEDIUM",Policy_Config!$B$28,Policy_Config!$B$29)))) -> 10 | AM13: =IF(AG13<>"OK","",SUM(AI13:AL13)) -> 60 | AN13: =IF(AG13<>"OK","REVIEW",IF(AM13>=Policy_Config!$B$5,"P0",IF(AM13>=Policy_Config!$B$6,"P1",IF(AM13>=Policy_Config!$B$7,"P2","P3")))) -> P1 | AO13: =IF(AG13<>"OK","NEEDS_REVIEW","FINAL") -> FINAL | AP13: =IF(AG13<>"OK","LOW","HIGH") -> HIGH | AQ13: =IF(OR(AN13="P0",AN13="P1",AH13=TRUE),"UPSERT_TICKET",IF(AO13="NEEDS_REVIEW","REVIEW_QUEUE","NO_IMMEDIATE_TICKET")) -> UPSERT_TICKET | AR13: SSVC.EXPLOITATION.MODERATE | SSVC.AUTOMATABLE.YES | SSVC.BUSINESS_IMPACT.HIGH | VPS.THRESHOLD.P1 | AS13: Public dashboard with high-value operational metadata.
A14: SYN-010 | B14: SYNTHETIC_TEST_CASE | C14: finding-8f31ab | D14: WIZ | E14: wiz-finding-010 | F14: CVE-2026-99010 | G14: asset-ml-api-prod-01 | H14: Machine-learning inference API | I14: python-pickle-loader | J14: 1.8.0 | K14: 9 | L14: Unsafe deserialization in model loading endpoint | N14: ERROR | Q14: ERROR | R14: TRUE | S14: KNOWN | T14: TRUE | U14: KNOWN | V14: TRUE | W14: KNOWN | X14: CRITICAL | Y14: KNOWN | Z14: Payload schema validation; egress filtering | AA14: FALSE | AB14: WIZ;CMDB;FIRST_EPSS_ERROR;CISA_KEV_ERROR | AC14: 46243.44 | AD14: LOW | AE14: snapshot-20260809-000154 | AF14: 2026.07-pilot.1 | AG14: =IF(OR(N14<>"KNOWN",Q14<>"KNOWN",S14<>"KNOWN",U14<>"KNOWN",W14<>"KNOWN",Y14<>"KNOWN"),"NEEDS_REVIEW","OK") -> NEEDS_REVIEW | AH14: =IF(OR(AND(Q14="KNOWN",P14=TRUE),AA14=TRUE),TRUE,FALSE) -> FALSE | AI14: =IF(AG14<>"OK",0,IF(AH14=TRUE,Policy_Config!$B$11,IF(M14>=Policy_Config!$C$12,Policy_Config!$B$12,IF(M14>=Policy_Config!$C$13,Policy_Config!$B$13,IF(M14>=Policy_Config!$C$14,Policy_Config!$B$14,Policy_Config!$B$15))))) -> 0 | AJ14: =IF(AG14<>"OK",0,IF(AND(R14=TRUE,V14=TRUE),Policy_Config!$B$17,IF(OR(R14=TRUE,V14=TRUE),Policy_Config!$B$18,Policy_Config!$B$19))) -> 0 | AK14: =IF(AG14<>"OK",0,IF(T14=FALSE,Policy_Config!$B$21,IF(K14>=Policy_Config!$C$22,Policy_Config!$B$22,IF(K14>=Policy_Config!$C$23,Policy_Config!$B$23,Policy_Config!$B$24)))) -> 0 | AL14: =IF(AG14<>"OK",0,IF(X14="CRITICAL",Policy_Config!$B$26,IF(X14="HIGH",Policy_Config!$B$27,IF(X14="MEDIUM",Policy_Config!$B$28,Policy_Config!$B$29)))) -> 0 | AM14: =IF(AG14<>"OK","",SUM(AI14:AL14)) | AN14: =IF(AG14<>"OK","REVIEW",IF(AM14>=Policy_Config!$B$5,"P0",IF(AM14>=Policy_Config!$B$6,"P1",IF(AM14>=Policy_Config!$B$7,"P2","P3")))) -> REVIEW | AO14: =IF(AG14<>"OK","NEEDS_REVIEW","FINAL") -> NEEDS_REVIEW | AP14: =IF(AG14<>"OK","LOW","HIGH") -> LOW | AQ14: =IF(OR(AN14="P0",AN14="P1",AH14=TRUE),"UPSERT_TICKET",IF(AO14="NEEDS_REVIEW","REVIEW_QUEUE","NO_IMMEDIATE_TICKET")) -> REVIEW_QUEUE | AR14: QUALITY.CRITICAL_SOURCE_ERROR | ROUTE.NEEDS_REVIEW | AS14: Both threat-intelligence feeds failed; no final score allowed.
A15: SYN-011 | B15: SYNTHETIC_TEST_CASE | C15: finding-8f31ac | D15: WIZ | E15: wiz-finding-011 | F15: CVE-2026-99011 | G15: asset-node-api-prod-02 | H15: Node.js customer API | I15: lodash | J15: 4.17.20 | K15: 6.5 | L15: Prototype pollution in request transformation library | M15: 0.44 | N15: STALE | O15: 0.91 | P15: FALSE | Q15: STALE | R15: TRUE | S15: KNOWN | T15: TRUE | U15: KNOWN | V15: TRUE | W15: KNOWN | X15: MEDIUM | Y15: KNOWN | Z15: Input schema validation; API gateway | AA15: FALSE | AB15: WIZ;CMDB;FIRST_EPSS_LAST_KNOWN;CISA_KEV_LAST_KNOWN | AC15: 46243.441 | AD15: LOW | AE15: snapshot-20260809-000155 | AF15: 2026.07-pilot.1 | AG15: =IF(OR(N15<>"KNOWN",Q15<>"KNOWN",S15<>"KNOWN",U15<>"KNOWN",W15<>"KNOWN",Y15<>"KNOWN"),"NEEDS_REVIEW","OK") -> NEEDS_REVIEW | AH15: =IF(OR(AND(Q15="KNOWN",P15=TRUE),AA15=TRUE),TRUE,FALSE) -> FALSE | AI15: =IF(AG15<>"OK",0,IF(AH15=TRUE,Policy_Config!$B$11,IF(M15>=Policy_Config!$C$12,Policy_Config!$B$12,IF(M15>=Policy_Config!$C$13,Policy_Config!$B$13,IF(M15>=Policy_Config!$C$14,Policy_Config!$B$14,Policy_Config!$B$15))))) -> 0 | AJ15: =IF(AG15<>"OK",0,IF(AND(R15=TRUE,V15=TRUE),Policy_Config!$B$17,IF(OR(R15=TRUE,V15=TRUE),Policy_Config!$B$18,Policy_Config!$B$19))) -> 0 | AK15: =IF(AG15<>"OK",0,IF(T15=FALSE,Policy_Config!$B$21,IF(K15>=Policy_Config!$C$22,Policy_Config!$B$22,IF(K15>=Policy_Config!$C$23,Policy_Config!$B$23,Policy_Config!$B$24)))) -> 0 | AL15: =IF(AG15<>"OK",0,IF(X15="CRITICAL",Policy_Config!$B$26,IF(X15="HIGH",Policy_Config!$B$27,IF(X15="MEDIUM",Policy_Config!$B$28,Policy_Config!$B$29)))) -> 0 | AM15: =IF(AG15<>"OK","",SUM(AI15:AL15)) | AN15: =IF(AG15<>"OK","REVIEW",IF(AM15>=Policy_Config!$B$5,"P0",IF(AM15>=Policy_Config!$B$6,"P1",IF(AM15>=Policy_Config!$B$7,"P2","P3")))) -> REVIEW | AO15: =IF(AG15<>"OK","NEEDS_REVIEW","FINAL") -> NEEDS_REVIEW | AP15: =IF(AG15<>"OK","LOW","HIGH") -> LOW | AQ15: =IF(OR(AN15="P0",AN15="P1",AH15=TRUE),"UPSERT_TICKET",IF(AO15="NEEDS_REVIEW","REVIEW_QUEUE","NO_IMMEDIATE_TICKET")) -> REVIEW_QUEUE | AR15: QUALITY.STALE_SOURCE | ROUTE.NEEDS_REVIEW | AS15: Last-known-good feed exceeds warning age for this test case.
A16: SYN-012 | B16: SYNTHETIC_TEST_CASE | C16: finding-8f31ad | D16: WIZ | E16: wiz-finding-012 | F16: CVE-2026-99012 | G16: asset-media-worker-prod-01 | H16: Media processing worker | I16: imagemagick | J16: 7.1.1-10 | K16: 7.2 | L16: Parser issue in image processing library | M16: 0.12 | N16: KNOWN | O16: 0.62 | P16: FALSE | Q16: KNOWN | R16: FALSE | S16: KNOWN | T16: FALSE | U16: KNOWN | V16: FALSE | W16: KNOWN | X16: LOW | Y16: KNOWN | Z16: Package present but code path disabled | AA16: FALSE | AB16: WIZ;CMDB;FIRST_EPSS;CISA_KEV | AC16: 46243.442 | AD16: HIGH | AE16: snapshot-20260809-000156 | AF16: 2026.07-pilot.1 | AG16: =IF(OR(N16<>"KNOWN",Q16<>"KNOWN",S16<>"KNOWN",U16<>"KNOWN",W16<>"KNOWN",Y16<>"KNOWN"),"NEEDS_REVIEW","OK") -> OK | AH16: =IF(OR(AND(Q16="KNOWN",P16=TRUE),AA16=TRUE),TRUE,FALSE) -> FALSE | AI16: =IF(AG16<>"OK",0,IF(AH16=TRUE,Policy_Config!$B$11,IF(M16>=Policy_Config!$C$12,Policy_Config!$B$12,IF(M16>=Policy_Config!$C$13,Policy_Config!$B$13,IF(M16>=Policy_Config!$C$14,Policy_Config!$B$14,Policy_Config!$B$15))))) -> 10 | AJ16: =IF(AG16<>"OK",0,IF(AND(R16=TRUE,V16=TRUE),Policy_Config!$B$17,IF(OR(R16=TRUE,V16=TRUE),Policy_Config!$B$18,Policy_Config!$B$19))) -> 0 | AK16: =IF(AG16<>"OK",0,IF(T16=FALSE,Policy_Config!$B$21,IF(K16>=Policy_Config!$C$22,Policy_Config!$B$22,IF(K16>=Policy_Config!$C$23,Policy_Config!$B$23,Policy_Config!$B$24)))) -> 0 | AL16: =IF(AG16<>"OK",0,IF(X16="CRITICAL",Policy_Config!$B$26,IF(X16="HIGH",Policy_Config!$B$27,IF(X16="MEDIUM",Policy_Config!$B$28,Policy_Config!$B$29)))) -> 2 | AM16: =IF(AG16<>"OK","",SUM(AI16:AL16)) -> 12 | AN16: =IF(AG16<>"OK","REVIEW",IF(AM16>=Policy_Config!$B$5,"P0",IF(AM16>=Policy_Config!$B$6,"P1",IF(AM16>=Policy_Config!$B$7,"P2","P3")))) -> P3 | AO16: =IF(AG16<>"OK","NEEDS_REVIEW","FINAL") -> FINAL | AP16: =IF(AG16<>"OK","LOW","HIGH") -> HIGH | AQ16: =IF(OR(AN16="P0",AN16="P1",AH16=TRUE),"UPSERT_TICKET",IF(AO16="NEEDS_REVIEW","REVIEW_QUEUE","NO_IMMEDIATE_TICKET")) -> NO_IMMEDIATE_TICKET | AR16: SSVC.RUNTIME_APPLICABILITY.FALSE | SSVC.ATTACK_PATH.NOT_REACHABLE | VPS.THRESHOLD.P3 | AS16: Package is present but the vulnerable runtime path is not loaded.
A17: SYN-013 | B17: SYNTHETIC_TEST_CASE | C17: finding-8f31ae | D17: WIZ | E17: wiz-finding-013 | F17: CVE-2026-99013 | G17: asset-order-service-prod-01 | H17: Order service application | I17: weblogic-server | J17: 14.1.1 | K17: 9.8 | L17: Remote code execution in application server | M17: 0.94 | N17: KNOWN | O17: 0.997 | P17: FALSE | Q17: KNOWN | R17: TRUE | S17: KNOWN | T17: TRUE | U17: KNOWN | V17: TRUE | W17: KNOWN | X17: CRITICAL | Y17: KNOWN | Z17: WAF; restricted admin console | AA17: FALSE | AB17: WIZ;CMDB;FIRST_EPSS;CISA_KEV | AC17: 46243.444 | AD17: HIGH | AE17: snapshot-20260809-000157 | AF17: 2026.07-pilot.1 | AG17: =IF(OR(N17<>"KNOWN",Q17<>"KNOWN",S17<>"KNOWN",U17<>"KNOWN",W17<>"KNOWN",Y17<>"KNOWN"),"NEEDS_REVIEW","OK") -> OK | AH17: =IF(OR(AND(Q17="KNOWN",P17=TRUE),AA17=TRUE),TRUE,FALSE) -> FALSE | AI17: =IF(AG17<>"OK",0,IF(AH17=TRUE,Policy_Config!$B$11,IF(M17>=Policy_Config!$C$12,Policy_Config!$B$12,IF(M17>=Policy_Config!$C$13,Policy_Config!$B$13,IF(M17>=Policy_Config!$C$14,Policy_Config!$B$14,Policy_Config!$B$15))))) -> 25 | AJ17: =IF(AG17<>"OK",0,IF(AND(R17=TRUE,V17=TRUE),Policy_Config!$B$17,IF(OR(R17=TRUE,V17=TRUE),Policy_Config!$B$18,Policy_Config!$B$19))) -> 20 | AK17: =IF(AG17<>"OK",0,IF(T17=FALSE,Policy_Config!$B$21,IF(K17>=Policy_Config!$C$22,Policy_Config!$B$22,IF(K17>=Policy_Config!$C$23,Policy_Config!$B$23,Policy_Config!$B$24)))) -> 20 | AL17: =IF(AG17<>"OK",0,IF(X17="CRITICAL",Policy_Config!$B$26,IF(X17="HIGH",Policy_Config!$B$27,IF(X17="MEDIUM",Policy_Config!$B$28,Policy_Config!$B$29)))) -> 15 | AM17: =IF(AG17<>"OK","",SUM(AI17:AL17)) -> 80 | AN17: =IF(AG17<>"OK","REVIEW",IF(AM17>=Policy_Config!$B$5,"P0",IF(AM17>=Policy_Config!$B$6,"P1",IF(AM17>=Policy_Config!$B$7,"P2","P3")))) -> P0 | AO17: =IF(AG17<>"OK","NEEDS_REVIEW","FINAL") -> FINAL | AP17: =IF(AG17<>"OK","LOW","HIGH") -> HIGH | AQ17: =IF(OR(AN17="P0",AN17="P1",AH17=TRUE),"UPSERT_TICKET",IF(AO17="NEEDS_REVIEW","REVIEW_QUEUE","NO_IMMEDIATE_TICKET")) -> UPSERT_TICKET | AR17: SSVC.EXPLOITATION.HIGH | SSVC.AUTOMATABLE.YES | SSVC.TECHNICAL_IMPACT.HIGH | VPS.THRESHOLD.P0 | AS17: High EPSS without KEV; still crosses P0 threshold.
A18: SYN-014 | B18: SYNTHETIC_TEST_CASE | C18: finding-8f31af | D18: WIZ | E18: wiz-finding-014 | F18: CVE-2026-99014 | G18: asset-dev-gitlab-prod-01 | H18: Developer collaboration platform | I18: gitlab-ce | J18: 16.3.1 | K18: 6.1 | L18: Stored cross-site scripting in project administration | M18: 0.08 | N18: KNOWN | O18: 0.41 | P18: FALSE | Q18: KNOWN | R18: TRUE | S18: KNOWN | T18: TRUE | U18: KNOWN | V18: TRUE | W18: KNOWN | X18: MEDIUM | Y18: KNOWN | Z18: Content security policy; SSO | AA18: FALSE | AB18: WIZ;CMDB;FIRST_EPSS;CISA_KEV | AC18: 46243.445 | AD18: HIGH | AE18: snapshot-20260809-000158 | AF18: 2026.07-pilot.1 | AG18: =IF(OR(N18<>"KNOWN",Q18<>"KNOWN",S18<>"KNOWN",U18<>"KNOWN",W18<>"KNOWN",Y18<>"KNOWN"),"NEEDS_REVIEW","OK") -> OK | AH18: =IF(OR(AND(Q18="KNOWN",P18=TRUE),AA18=TRUE),TRUE,FALSE) -> FALSE | AI18: =IF(AG18<>"OK",0,IF(AH18=TRUE,Policy_Config!$B$11,IF(M18>=Policy_Config!$C$12,Policy_Config!$B$12,IF(M18>=Policy_Config!$C$13,Policy_Config!$B$13,IF(M18>=Policy_Config!$C$14,Policy_Config!$B$14,Policy_Config!$B$15))))) -> 10 | AJ18: =IF(AG18<>"OK",0,IF(AND(R18=TRUE,V18=TRUE),Policy_Config!$B$17,IF(OR(R18=TRUE,V18=TRUE),Policy_Config!$B$18,Policy_Config!$B$19))) -> 20 | AK18: =IF(AG18<>"OK",0,IF(T18=FALSE,Policy_Config!$B$21,IF(K18>=Policy_Config!$C$22,Policy_Config!$B$22,IF(K18>=Policy_Config!$C$23,Policy_Config!$B$23,Policy_Config!$B$24)))) -> 10 | AL18: =IF(AG18<>"OK",0,IF(X18="CRITICAL",Policy_Config!$B$26,IF(X18="HIGH",Policy_Config!$B$27,IF(X18="MEDIUM",Policy_Config!$B$28,Policy_Config!$B$29)))) -> 5 | AM18: =IF(AG18<>"OK","",SUM(AI18:AL18)) -> 45 | AN18: =IF(AG18<>"OK","REVIEW",IF(AM18>=Policy_Config!$B$5,"P0",IF(AM18>=Policy_Config!$B$6,"P1",IF(AM18>=Policy_Config!$B$7,"P2","P3")))) -> P2 | AO18: =IF(AG18<>"OK","NEEDS_REVIEW","FINAL") -> FINAL | AP18: =IF(AG18<>"OK","LOW","HIGH") -> HIGH | AQ18: =IF(OR(AN18="P0",AN18="P1",AH18=TRUE),"UPSERT_TICKET",IF(AO18="NEEDS_REVIEW","REVIEW_QUEUE","NO_IMMEDIATE_TICKET")) -> NO_IMMEDIATE_TICKET | AR18: SSVC.EXPLOITATION.LOW | SSVC.AUTOMATABLE.YES | VPS.THRESHOLD.P2 | AS18: Lower exploit probability and moderate service impact.
A19: SYN-015 | B19: SYNTHETIC_TEST_CASE | C19: finding-8f31b0 | D19: WIZ | E19: wiz-finding-015 | F19: CVE-2026-99015 | G19: asset-cache-cluster-prod-01 | H19: Internal caching cluster | I19: redis | J19: 7.0.12 | K19: 8.8 | L19: Command injection through cache administration interface | M19: 0.72 | N19: KNOWN | O19: 0.973 | P19: FALSE | Q19: KNOWN | R19: FALSE | S19: KNOWN | T19: TRUE | U19: KNOWN | V19: TRUE | W19: KNOWN | X19: HIGH | Y19: KNOWN | Z19: Network segmentation; ACLs | AA19: TRUE | AB19: WIZ;CMDB;FIRST_EPSS;CISA_KEV;INTERNAL_THREAT_INTEL | AC19: 46243.447 | AD19: HIGH | AE19: snapshot-20260809-000159 | AF19: 2026.07-pilot.1 | AG19: =IF(OR(N19<>"KNOWN",Q19<>"KNOWN",S19<>"KNOWN",U19<>"KNOWN",W19<>"KNOWN",Y19<>"KNOWN"),"NEEDS_REVIEW","OK") -> OK | AH19: =IF(OR(AND(Q19="KNOWN",P19=TRUE),AA19=TRUE),TRUE,FALSE) -> TRUE | AI19: =IF(AG19<>"OK",0,IF(AH19=TRUE,Policy_Config!$B$11,IF(M19>=Policy_Config!$C$12,Policy_Config!$B$12,IF(M19>=Policy_Config!$C$13,Policy_Config!$B$13,IF(M19>=Policy_Config!$C$14,Policy_Config!$B$14,Policy_Config!$B$15))))) -> 30 | AJ19: =IF(AG19<>"OK",0,IF(AND(R19=TRUE,V19=TRUE),Policy_Config!$B$17,IF(OR(R19=TRUE,V19=TRUE),Policy_Config!$B$18,Policy_Config!$B$19))) -> 10 | AK19: =IF(AG19<>"OK",0,IF(T19=FALSE,Policy_Config!$B$21,IF(K19>=Policy_Config!$C$22,Policy_Config!$B$22,IF(K19>=Policy_Config!$C$23,Policy_Config!$B$23,Policy_Config!$B$24)))) -> 15 | AL19: =IF(AG19<>"OK",0,IF(X19="CRITICAL",Policy_Config!$B$26,IF(X19="HIGH",Policy_Config!$B$27,IF(X19="MEDIUM",Policy_Config!$B$28,Policy_Config!$B$29)))) -> 10 | AM19: =IF(AG19<>"OK","",SUM(AI19:AL19)) -> 65 | AN19: =IF(AG19<>"OK","REVIEW",IF(AM19>=Policy_Config!$B$5,"P0",IF(AM19>=Policy_Config!$B$6,"P1",IF(AM19>=Policy_Config!$B$7,"P2","P3")))) -> P1 | AO19: =IF(AG19<>"OK","NEEDS_REVIEW","FINAL") -> FINAL | AP19: =IF(AG19<>"OK","LOW","HIGH") -> HIGH | AQ19: =IF(OR(AN19="P0",AN19="P1",AH19=TRUE),"UPSERT_TICKET",IF(AO19="NEEDS_REVIEW","REVIEW_QUEUE","NO_IMMEDIATE_TICKET")) -> UPSERT_TICKET | AR19: INTERNAL_ACTIVE_EXPLOITATION | SSVC.AUTOMATABLE.PARTIAL | SSVC.BUSINESS_IMPACT.HIGH | VPS.THRESHOLD.P1 | AS19: Internal threat intelligence confirms active exploitation; mandatory remediation is true even though KEV is false.
A20: SYN-016 | B20: SYNTHETIC_TEST_CASE | C20: finding-8f31b1 | D20: WIZ | E20: wiz-finding-016 | F20: CVE-2026-99016 | G20: asset-orders-db-prod-01 | H20: Orders database service | I20: jdbc-driver | J20: 42.6.0 | K20: 9.8 | L20: SQL injection in database-backed order query | M20: 0.97 | N20: KNOWN | O20: 0.999 | P20: FALSE | Q20: KNOWN | R20: TRUE | S20: KNOWN | T20: TRUE | U20: KNOWN | W20: UNKNOWN | X20: CRITICAL | Y20: KNOWN | Z20: Parameterized queries on known routes | AA20: FALSE | AB20: WIZ;CMDB;FIRST_EPSS;CISA_KEV;ATTACK_PATH_PENDING | AC20: 46243.448 | AD20: LOW | AE20: snapshot-20260809-000160 | AF20: 2026.07-pilot.1 | AG20: =IF(OR(N20<>"KNOWN",Q20<>"KNOWN",S20<>"KNOWN",U20<>"KNOWN",W20<>"KNOWN",Y20<>"KNOWN"),"NEEDS_REVIEW","OK") -> NEEDS_REVIEW | AH20: =IF(OR(AND(Q20="KNOWN",P20=TRUE),AA20=TRUE),TRUE,FALSE) -> FALSE | AI20: =IF(AG20<>"OK",0,IF(AH20=TRUE,Policy_Config!$B$11,IF(M20>=Policy_Config!$C$12,Policy_Config!$B$12,IF(M20>=Policy_Config!$C$13,Policy_Config!$B$13,IF(M20>=Policy_Config!$C$14,Policy_Config!$B$14,Policy_Config!$B$15))))) -> 0 | AJ20: =IF(AG20<>"OK",0,IF(AND(R20=TRUE,V20=TRUE),Policy_Config!$B$17,IF(OR(R20=TRUE,V20=TRUE),Policy_Config!$B$18,Policy_Config!$B$19))) -> 0 | AK20: =IF(AG20<>"OK",0,IF(T20=FALSE,Policy_Config!$B$21,IF(K20>=Policy_Config!$C$22,Policy_Config!$B$22,IF(K20>=Policy_Config!$C$23,Policy_Config!$B$23,Policy_Config!$B$24)))) -> 0 | AL20: =IF(AG20<>"OK",0,IF(X20="CRITICAL",Policy_Config!$B$26,IF(X20="HIGH",Policy_Config!$B$27,IF(X20="MEDIUM",Policy_Config!$B$28,Policy_Config!$B$29)))) -> 0 | AM20: =IF(AG20<>"OK","",SUM(AI20:AL20)) | AN20: =IF(AG20<>"OK","REVIEW",IF(AM20>=Policy_Config!$B$5,"P0",IF(AM20>=Policy_Config!$B$6,"P1",IF(AM20>=Policy_Config!$B$7,"P2","P3")))) -> REVIEW | AO20: =IF(AG20<>"OK","NEEDS_REVIEW","FINAL") -> NEEDS_REVIEW | AP20: =IF(AG20<>"OK","LOW","HIGH") -> LOW | AQ20: =IF(OR(AN20="P0",AN20="P1",AH20=TRUE),"UPSERT_TICKET",IF(AO20="NEEDS_REVIEW","REVIEW_QUEUE","NO_IMMEDIATE_TICKET")) -> REVIEW_QUEUE | AR20: QUALITY.ATTACK_PATH_UNKNOWN | ROUTE.NEEDS_REVIEW | AS20: High threat indicators but reachability evidence is not yet confirmed.
A21: SYN-017 | B21: SYNTHETIC_TEST_CASE | C21: finding-8f31b2 | D21: WIZ | E21: wiz-finding-017 | F21: CVE-2026-99017 | G21: asset-mail-exchange-prod-01 | H21: Enterprise mail server | I21: exchange-server | J21: 2019-cu12 | K21: 9.8 | L21: Authentication bypass in mail access service | M21: 0.88 | N21: KNOWN | O21: 0.989 | P21: TRUE | Q21: KNOWN | R21: TRUE | S21: KNOWN | T21: TRUE | U21: KNOWN | V21: TRUE | W21: KNOWN | X21: CRITICAL | Y21: KNOWN | Z21: MFA for admin; mail gateway filtering | AA21: FALSE | AB21: WIZ;CMDB;FIRST_EPSS;CISA_KEV | AC21: 46243.449 | AD21: HIGH | AE21: snapshot-20260809-000161 | AF21: 2026.07-pilot.1 | AG21: =IF(OR(N21<>"KNOWN",Q21<>"KNOWN",S21<>"KNOWN",U21<>"KNOWN",W21<>"KNOWN",Y21<>"KNOWN"),"NEEDS_REVIEW","OK") -> OK | AH21: =IF(OR(AND(Q21="KNOWN",P21=TRUE),AA21=TRUE),TRUE,FALSE) -> TRUE | AI21: =IF(AG21<>"OK",0,IF(AH21=TRUE,Policy_Config!$B$11,IF(M21>=Policy_Config!$C$12,Policy_Config!$B$12,IF(M21>=Policy_Config!$C$13,Policy_Config!$B$13,IF(M21>=Policy_Config!$C$14,Policy_Config!$B$14,Policy_Config!$B$15))))) -> 30 | AJ21: =IF(AG21<>"OK",0,IF(AND(R21=TRUE,V21=TRUE),Policy_Config!$B$17,IF(OR(R21=TRUE,V21=TRUE),Policy_Config!$B$18,Policy_Config!$B$19))) -> 20 | AK21: =IF(AG21<>"OK",0,IF(T21=FALSE,Policy_Config!$B$21,IF(K21>=Policy_Config!$C$22,Policy_Config!$B$22,IF(K21>=Policy_Config!$C$23,Policy_Config!$B$23,Policy_Config!$B$24)))) -> 20 | AL21: =IF(AG21<>"OK",0,IF(X21="CRITICAL",Policy_Config!$B$26,IF(X21="HIGH",Policy_Config!$B$27,IF(X21="MEDIUM",Policy_Config!$B$28,Policy_Config!$B$29)))) -> 15 | AM21: =IF(AG21<>"OK","",SUM(AI21:AL21)) -> 85 | AN21: =IF(AG21<>"OK","REVIEW",IF(AM21>=Policy_Config!$B$5,"P0",IF(AM21>=Policy_Config!$B$6,"P1",IF(AM21>=Policy_Config!$B$7,"P2","P3")))) -> P0 | AO21: =IF(AG21<>"OK","NEEDS_REVIEW","FINAL") -> FINAL | AP21: =IF(AG21<>"OK","LOW","HIGH") -> HIGH | AQ21: =IF(OR(AN21="P0",AN21="P1",AH21=TRUE),"UPSERT_TICKET",IF(AO21="NEEDS_REVIEW","REVIEW_QUEUE","NO_IMMEDIATE_TICKET")) -> UPSERT_TICKET | AR21: SSVC.EXPLOITATION.ACTIVE | SSVC.AUTOMATABLE.YES | SSVC.TECHNICAL_IMPACT.HIGH | VPS.THRESHOLD.P0 | AS21: P0 KEV finding on a business-critical service.
A22: SYN-018 | B22: SYNTHETIC_TEST_CASE | C22: finding-8f31b3 | D22: WIZ | E22: wiz-finding-018 | F22: CVE-2026-99018 | G22: asset-k8s-dashboard-prod-01 | H22: Kubernetes dashboard | I22: kubernetes-dashboard | J22: 2.7.0 | K22: 8 | L22: Authorization weakness in cluster dashboard | M22: 0.22 | N22: KNOWN | O22: 0.78 | P22: FALSE | Q22: KNOWN | R22: FALSE | S22: KNOWN | T22: TRUE | U22: KNOWN | V22: FALSE | W22: KNOWN | X22: MEDIUM | Y22: KNOWN | Z22: Private ingress; RBAC; network policy | AA22: FALSE | AB22: WIZ;CMDB;FIRST_EPSS;CISA_KEV | AC22: 46243.451 | AD22: HIGH | AE22: snapshot-20260809-000162 | AF22: 2026.07-pilot.1 | AG22: =IF(OR(N22<>"KNOWN",Q22<>"KNOWN",S22<>"KNOWN",U22<>"KNOWN",W22<>"KNOWN",Y22<>"KNOWN"),"NEEDS_REVIEW","OK") -> OK | AH22: =IF(OR(AND(Q22="KNOWN",P22=TRUE),AA22=TRUE),TRUE,FALSE) -> FALSE | AI22: =IF(AG22<>"OK",0,IF(AH22=TRUE,Policy_Config!$B$11,IF(M22>=Policy_Config!$C$12,Policy_Config!$B$12,IF(M22>=Policy_Config!$C$13,Policy_Config!$B$13,IF(M22>=Policy_Config!$C$14,Policy_Config!$B$14,Policy_Config!$B$15))))) -> 10 | AJ22: =IF(AG22<>"OK",0,IF(AND(R22=TRUE,V22=TRUE),Policy_Config!$B$17,IF(OR(R22=TRUE,V22=TRUE),Policy_Config!$B$18,Policy_Config!$B$19))) -> 0 | AK22: =IF(AG22<>"OK",0,IF(T22=FALSE,Policy_Config!$B$21,IF(K22>=Policy_Config!$C$22,Policy_Config!$B$22,IF(K22>=Policy_Config!$C$23,Policy_Config!$B$23,Policy_Config!$B$24)))) -> 15 | AL22: =IF(AG22<>"OK",0,IF(X22="CRITICAL",Policy_Config!$B$26,IF(X22="HIGH",Policy_Config!$B$27,IF(X22="MEDIUM",Policy_Config!$B$28,Policy_Config!$B$29)))) -> 5 | AM22: =IF(AG22<>"OK","",SUM(AI22:AL22)) -> 30 | AN22: =IF(AG22<>"OK","REVIEW",IF(AM22>=Policy_Config!$B$5,"P0",IF(AM22>=Policy_Config!$B$6,"P1",IF(AM22>=Policy_Config!$B$7,"P2","P3")))) -> P3 | AO22: =IF(AG22<>"OK","NEEDS_REVIEW","FINAL") -> FINAL | AP22: =IF(AG22<>"OK","LOW","HIGH") -> HIGH | AQ22: =IF(OR(AN22="P0",AN22="P1",AH22=TRUE),"UPSERT_TICKET",IF(AO22="NEEDS_REVIEW","REVIEW_QUEUE","NO_IMMEDIATE_TICKET")) -> NO_IMMEDIATE_TICKET | AR22: SSVC.EXPLOITATION.LOW | SSVC.ATTACK_PATH.NOT_REACHABLE | VPS.THRESHOLD.P3 | AS22: Private dashboard with no confirmed attack path.
A23: SYN-019 | B23: SYNTHETIC_TEST_CASE | C23: finding-8f31b4 | D23: WIZ | E23: wiz-finding-019 | F23: CVE-2026-99019 | G23: asset-auth-api-prod-01 | H23: Identity and authentication API | I23: jvm-logging-library | J23: 2.19.0 | K23: 9.8 | L23: Remote code execution through logging interpolation | M23: 0.82 | N23: KNOWN | O23: 0.984 | P23: FALSE | Q23: KNOWN | R23: TRUE | S23: KNOWN | T23: TRUE | U23: KNOWN | V23: TRUE | W23: KNOWN | X23: CRITICAL | Y23: KNOWN | Z23: WAF; outbound DNS policy | AA23: FALSE | AB23: WIZ;CMDB;FIRST_EPSS;CISA_KEV | AC23: 46243.452 | AD23: HIGH | AE23: snapshot-20260809-000163 | AF23: 2026.07-pilot.1 | AG23: =IF(OR(N23<>"KNOWN",Q23<>"KNOWN",S23<>"KNOWN",U23<>"KNOWN",W23<>"KNOWN",Y23<>"KNOWN"),"NEEDS_REVIEW","OK") -> OK | AH23: =IF(OR(AND(Q23="KNOWN",P23=TRUE),AA23=TRUE),TRUE,FALSE) -> FALSE | AI23: =IF(AG23<>"OK",0,IF(AH23=TRUE,Policy_Config!$B$11,IF(M23>=Policy_Config!$C$12,Policy_Config!$B$12,IF(M23>=Policy_Config!$C$13,Policy_Config!$B$13,IF(M23>=Policy_Config!$C$14,Policy_Config!$B$14,Policy_Config!$B$15))))) -> 20 | AJ23: =IF(AG23<>"OK",0,IF(AND(R23=TRUE,V23=TRUE),Policy_Config!$B$17,IF(OR(R23=TRUE,V23=TRUE),Policy_Config!$B$18,Policy_Config!$B$19))) -> 20 | AK23: =IF(AG23<>"OK",0,IF(T23=FALSE,Policy_Config!$B$21,IF(K23>=Policy_Config!$C$22,Policy_Config!$B$22,IF(K23>=Policy_Config!$C$23,Policy_Config!$B$23,Policy_Config!$B$24)))) -> 20 | AL23: =IF(AG23<>"OK",0,IF(X23="CRITICAL",Policy_Config!$B$26,IF(X23="HIGH",Policy_Config!$B$27,IF(X23="MEDIUM",Policy_Config!$B$28,Policy_Config!$B$29)))) -> 15 | AM23: =IF(AG23<>"OK","",SUM(AI23:AL23)) -> 75 | AN23: =IF(AG23<>"OK","REVIEW",IF(AM23>=Policy_Config!$B$5,"P0",IF(AM23>=Policy_Config!$B$6,"P1",IF(AM23>=Policy_Config!$B$7,"P2","P3")))) -> P1 | AO23: =IF(AG23<>"OK","NEEDS_REVIEW","FINAL") -> FINAL | AP23: =IF(AG23<>"OK","LOW","HIGH") -> HIGH | AQ23: =IF(OR(AN23="P0",AN23="P1",AH23=TRUE),"UPSERT_TICKET",IF(AO23="NEEDS_REVIEW","REVIEW_QUEUE","NO_IMMEDIATE_TICKET")) -> UPSERT_TICKET | AR23: SSVC.EXPLOITATION.HIGH | SSVC.AUTOMATABLE.YES | SSVC.TECHNICAL_IMPACT.HIGH | VPS.THRESHOLD.P0 | AS23: High-impact identity service with public exposure.
A24: SYN-020 | B24: SYNTHETIC_TEST_CASE | C24: finding-8f31b5 | D24: WIZ | E24: wiz-finding-020 | F24: CVE-2026-99020 | G24: asset-file-transfer-prod-01 | H24: Managed file transfer service | I24: sftp-server | J24: 4.3.1 | K24: 8.6 | L24: Path traversal in file transfer request handling | M24: 0.59 | N24: KNOWN | O24: 0.95 | P24: FALSE | Q24: KNOWN | R24: TRUE | S24: KNOWN | T24: TRUE | U24: KNOWN | V24: TRUE | W24: KNOWN | X24: HIGH | Y24: UNKNOWN | Z24: Chroot directory; file allowlist | AA24: FALSE | AB24: WIZ;CMDB_PENDING;FIRST_EPSS;CISA_KEV | AC24: 46243.453 | AD24: LOW | AE24: snapshot-20260809-000164 | AF24: 2026.07-pilot.1 | AG24: =IF(OR(N24<>"KNOWN",Q24<>"KNOWN",S24<>"KNOWN",U24<>"KNOWN",W24<>"KNOWN",Y24<>"KNOWN"),"NEEDS_REVIEW","OK") -> NEEDS_REVIEW | AH24: =IF(OR(AND(Q24="KNOWN",P24=TRUE),AA24=TRUE),TRUE,FALSE) -> FALSE | AI24: =IF(AG24<>"OK",0,IF(AH24=TRUE,Policy_Config!$B$11,IF(M24>=Policy_Config!$C$12,Policy_Config!$B$12,IF(M24>=Policy_Config!$C$13,Policy_Config!$B$13,IF(M24>=Policy_Config!$C$14,Policy_Config!$B$14,Policy_Config!$B$15))))) -> 0 | AJ24: =IF(AG24<>"OK",0,IF(AND(R24=TRUE,V24=TRUE),Policy_Config!$B$17,IF(OR(R24=TRUE,V24=TRUE),Policy_Config!$B$18,Policy_Config!$B$19))) -> 0 | AK24: =IF(AG24<>"OK",0,IF(T24=FALSE,Policy_Config!$B$21,IF(K24>=Policy_Config!$C$22,Policy_Config!$B$22,IF(K24>=Policy_Config!$C$23,Policy_Config!$B$23,Policy_Config!$B$24)))) -> 0 | AL24: =IF(AG24<>"OK",0,IF(X24="CRITICAL",Policy_Config!$B$26,IF(X24="HIGH",Policy_Config!$B$27,IF(X24="MEDIUM",Policy_Config!$B$28,Policy_Config!$B$29)))) -> 0 | AM24: =IF(AG24<>"OK","",SUM(AI24:AL24)) | AN24: =IF(AG24<>"OK","REVIEW",IF(AM24>=Policy_Config!$B$5,"P0",IF(AM24>=Policy_Config!$B$6,"P1",IF(AM24>=Policy_Config!$B$7,"P2","P3")))) -> REVIEW | AO24: =IF(AG24<>"OK","NEEDS_REVIEW","FINAL") -> NEEDS_REVIEW | AP24: =IF(AG24<>"OK","LOW","HIGH") -> LOW | AQ24: =IF(OR(AN24="P0",AN24="P1",AH24=TRUE),"UPSERT_TICKET",IF(AO24="NEEDS_REVIEW","REVIEW_QUEUE","NO_IMMEDIATE_TICKET")) -> REVIEW_QUEUE | AR24: QUALITY.BUSINESS_CONTEXT_UNKNOWN | ROUTE.NEEDS_REVIEW | AS24: Business criticality is awaiting authoritative CMDB confirmation.

Sheet Evidence_Metadata
A1: EvidenceValue Metadata - Synthetic Fixtures
A2: This sheet models the source, freshness, status, timestamp, and confidence attached to each evidence value.
A4: Test_Case_ID | B4: Evidence_Snapshot_ID | C4: Finding_Instance_ID | D4: Field_Name | E4: Value | F4: Value_Type | G4: Status | H4: Source | I4: Source_Timestamp | J4: Retrieved_At | K4: Confidence | L4: Processing_Note
A5: SYN-001 | B5: snapshot-20260809-000145 | C5: finding-8f31a2 | D5: CVSS_BASE_SCORE | E5: 10 | F5: number | G5: KNOWN | H5: NVD_OR_SCANNER | I5: 46242.25 | J5: 46243.427 | K5: HIGH | L5: Severity baseline; validated 0-10.
A6: SYN-001 | B6: snapshot-20260809-000145 | C6: finding-8f31a2 | D6: EPSS_PROBABILITY | E6: 0.99999 | F6: number | G6: KNOWN | H6: FIRST_EPSS | I6: 46242.25 | J6: 46243.427 | K6: HIGH | L6: Used as exploitation factor only when fresh and known.
A7: SYN-001 | B7: snapshot-20260809-000145 | C7: finding-8f31a2 | D7: EPSS_PERCENTILE | E7: 1 | F7: number | G7: KNOWN | H7: FIRST_EPSS | I7: 46242.25 | J7: 46243.427 | K7: HIGH | L7: Ranking/context only; never treated as probability.
A8: SYN-001 | B8: snapshot-20260809-000145 | C8: finding-8f31a2 | D8: KEV_STATUS | E8: TRUE | F8: boolean | G8: KNOWN | H8: CISA_KEV | I8: 46242.25 | J8: 46243.427 | K8: HIGH | L8: Known true or internal active exploitation creates mandatory remediation.
A9: SYN-001 | B9: snapshot-20260809-000145 | C9: finding-8f31a2 | D9: INTERNET_EXPOSURE | E9: TRUE | F9: boolean | G9: KNOWN | H9: WIZ_ASSET_GRAPH | I9: 46242.25 | J9: 46243.427 | K9: HIGH | L9: Contributes to exposure urgency.
A10: SYN-001 | B10: snapshot-20260809-000145 | C10: finding-8f31a2 | D10: RUNTIME_APPLICABILITY | E10: TRUE | F10: boolean | G10: KNOWN | H10: WIZ_RUNTIME_INVENTORY | I10: 46242.25 | J10: 46243.427 | K10: HIGH | L10: Confirms whether vulnerable code is loaded and used.
A11: SYN-001 | B11: snapshot-20260809-000145 | C11: finding-8f31a2 | D11: ATTACK_PATH_REACHABLE | E11: TRUE | F11: boolean | G11: KNOWN | H11: WIZ_ATTACK_PATH | I11: 46242.25 | J11: 46243.427 | K11: HIGH | L11: Required for reachability-based priority.
A12: SYN-001 | B12: snapshot-20260809-000145 | C12: finding-8f31a2 | D12: BUSINESS_CRITICALITY | E12: CRITICAL | F12: string | G12: KNOWN | H12: CMDB | I12: 46242.25 | J12: 46243.427 | K12: HIGH | L12: Must come from authoritative business context.
A13: SYN-002 | B13: snapshot-20260809-000146 | C13: finding-8f31a3 | D13: CVSS_BASE_SCORE | E13: 9.1 | F13: number | G13: KNOWN | H13: NVD_OR_SCANNER | I13: 46242.25 | J13: 46243.428 | K13: HIGH | L13: Severity baseline; validated 0-10.
A14: SYN-002 | B14: snapshot-20260809-000146 | C14: finding-8f31a3 | D14: EPSS_PROBABILITY | E14: 0.91 | F14: number | G14: KNOWN | H14: FIRST_EPSS | I14: 46242.25 | J14: 46243.428 | K14: HIGH | L14: Used as exploitation factor only when fresh and known.
A15: SYN-002 | B15: snapshot-20260809-000146 | C15: finding-8f31a3 | D15: EPSS_PERCENTILE | E15: 0.995 | F15: number | G15: KNOWN | H15: FIRST_EPSS | I15: 46242.25 | J15: 46243.428 | K15: HIGH | L15: Ranking/context only; never treated as probability.
A16: SYN-002 | B16: snapshot-20260809-000146 | C16: finding-8f31a3 | D16: KEV_STATUS | E16: TRUE | F16: boolean | G16: KNOWN | H16: CISA_KEV | I16: 46242.25 | J16: 46243.428 | K16: HIGH | L16: Known true or internal active exploitation creates mandatory remediation.
A17: SYN-002 | B17: snapshot-20260809-000146 | C17: finding-8f31a3 | D17: INTERNET_EXPOSURE | E17: TRUE | F17: boolean | G17: KNOWN | H17: WIZ_ASSET_GRAPH | I17: 46242.25 | J17: 46243.428 | K17: HIGH | L17: Contributes to exposure urgency.
A18: SYN-002 | B18: snapshot-20260809-000146 | C18: finding-8f31a3 | D18: RUNTIME_APPLICABILITY | E18: TRUE | F18: boolean | G18: KNOWN | H18: WIZ_RUNTIME_INVENTORY | I18: 46242.25 | J18: 46243.428 | K18: HIGH | L18: Confirms whether vulnerable code is loaded and used.
A19: SYN-002 | B19: snapshot-20260809-000146 | C19: finding-8f31a3 | D19: ATTACK_PATH_REACHABLE | E19: TRUE | F19: boolean | G19: KNOWN | H19: WIZ_ATTACK_PATH | I19: 46242.25 | J19: 46243.428 | K19: HIGH | L19: Required for reachability-based priority.
A20: SYN-002 | B20: snapshot-20260809-000146 | C20: finding-8f31a3 | D20: BUSINESS_CRITICALITY | E20: HIGH | F20: string | G20: KNOWN | H20: CMDB | I20: 46242.25 | J20: 46243.428 | K20: HIGH | L20: Must come from authoritative business context.
A21: SYN-003 | B21: snapshot-20260809-000147 | C21: finding-8f31a4 | D21: CVSS_BASE_SCORE | E21: 9.8 | F21: number | G21: KNOWN | H21: NVD_OR_SCANNER | I21: 46242.25 | J21: 46243.43 | K21: HIGH | L21: Severity baseline; validated 0-10.
A22: SYN-003 | B22: snapshot-20260809-000147 | C22: finding-8f31a4 | D22: EPSS_PROBABILITY | E22: 0.87 | F22: number | G22: KNOWN | H22: FIRST_EPSS | I22: 46242.25 | J22: 46243.43 | K22: HIGH | L22: Used as exploitation factor only when fresh and known.
A23: SYN-003 | B23: snapshot-20260809-000147 | C23: finding-8f31a4 | D23: EPSS_PERCENTILE | E23: 0.985 | F23: number | G23: KNOWN | H23: FIRST_EPSS | I23: 46242.25 | J23: 46243.43 | K23: HIGH | L23: Ranking/context only; never treated as probability.
A24: SYN-003 | B24: snapshot-20260809-000147 | C24: finding-8f31a4 | D24: KEV_STATUS | E24: FALSE | F24: boolean | G24: KNOWN | H24: CISA_KEV | I24: 46242.25 | J24: 46243.43 | K24: HIGH | L24: Known true or internal active exploitation creates mandatory remediation.
A25: SYN-003 | B25: snapshot-20260809-000147 | C25: finding-8f31a4 | D25: INTERNET_EXPOSURE | E25: FALSE | F25: boolean | G25: KNOWN | H25: WIZ_ASSET_GRAPH | I25: 46242.25 | J25: 46243.43 | K25: HIGH | L25: Contributes to exposure urgency.
A26: SYN-003 | B26: snapshot-20260809-000147 | C26: finding-8f31a4 | D26: RUNTIME_APPLICABILITY | E26: TRUE | F26: boolean | G26: KNOWN | H26: WIZ_RUNTIME_INVENTORY | I26: 46242.25 | J26: 46243.43 | K26: HIGH | L26: Confirms whether vulnerable code is loaded and used.
A27: SYN-003 | B27: snapshot-20260809-000147 | C27: finding-8f31a4 | D27: ATTACK_PATH_REACHABLE | E27: TRUE | F27: boolean | G27: KNOWN | H27: WIZ_ATTACK_PATH | I27: 46242.25 | J27: 46243.43 | K27: HIGH | L27: Required for reachability-based priority.
A28: SYN-003 | B28: snapshot-20260809-000147 | C28: finding-8f31a4 | D28: BUSINESS_CRITICALITY | E28: CRITICAL | F28: string | G28: KNOWN | H28: CMDB | I28: 46242.25 | J28: 46243.43 | K28: HIGH | L28: Must come from authoritative business context.
A29: SYN-004 | B29: snapshot-20260809-000148 | C29: finding-8f31a5 | D29: CVSS_BASE_SCORE | E29: 8.8 | F29: number | G29: KNOWN | H29: NVD_OR_SCANNER | I29: 46242.25 | J29: 46243.431 | K29: HIGH | L29: Severity baseline; validated 0-10.
A30: SYN-004 | B30: snapshot-20260809-000148 | C30: finding-8f31a5 | D30: EPSS_PROBABILITY | E30: 0.65 | F30: number | G30: KNOWN | H30: FIRST_EPSS | I30: 46242.25 | J30: 46243.431 | K30: HIGH | L30: Used as exploitation factor only when fresh and known.
A31: SYN-004 | B31: snapshot-20260809-000148 | C31: finding-8f31a5 | D31: EPSS_PERCENTILE | E31: 0.965 | F31: number | G31: KNOWN | H31: FIRST_EPSS | I31: 46242.25 | J31: 46243.431 | K31: HIGH | L31: Ranking/context only; never treated as probability.
A32: SYN-004 | B32: snapshot-20260809-000148 | C32: finding-8f31a5 | D32: KEV_STATUS | E32: FALSE | F32: boolean | G32: KNOWN | H32: CISA_KEV | I32: 46242.25 | J32: 46243.431 | K32: HIGH | L32: Known true or internal active exploitation creates mandatory remediation.
A33: SYN-004 | B33: snapshot-20260809-000148 | C33: finding-8f31a5 | D33: INTERNET_EXPOSURE | E33: TRUE | F33: boolean | G33: KNOWN | H33: WIZ_ASSET_GRAPH | I33: 46242.25 | J33: 46243.431 | K33: HIGH | L33: Contributes to exposure urgency.
A34: SYN-004 | B34: snapshot-20260809-000148 | C34: finding-8f31a5 | D34: RUNTIME_APPLICABILITY | E34: TRUE | F34: boolean | G34: KNOWN | H34: WIZ_RUNTIME_INVENTORY | I34: 46242.25 | J34: 46243.431 | K34: HIGH | L34: Confirms whether vulnerable code is loaded and used.
A35: SYN-004 | B35: snapshot-20260809-000148 | C35: finding-8f31a5 | D35: ATTACK_PATH_REACHABLE | E35: TRUE | F35: boolean | G35: KNOWN | H35: WIZ_ATTACK_PATH | I35: 46242.25 | J35: 46243.431 | K35: HIGH | L35: Required for reachability-based priority.
A36: SYN-004 | B36: snapshot-20260809-000148 | C36: finding-8f31a5 | D36: BUSINESS_CRITICALITY | E36: HIGH | F36: string | G36: KNOWN | H36: CMDB | I36: 46242.25 | J36: 46243.431 | K36: HIGH | L36: Must come from authoritative business context.
A37: SYN-005 | B37: snapshot-20260809-000149 | C37: finding-8f31a6 | D37: CVSS_BASE_SCORE | E37: 9.8 | F37: number | G37: KNOWN | H37: NVD_OR_SCANNER | I37: 46242.25 | J37: 46243.433 | K37: HIGH | L37: Severity baseline; validated 0-10.
A38: SYN-005 | B38: snapshot-20260809-000149 | C38: finding-8f31a6 | D38: EPSS_PROBABILITY | E38: 0.76 | F38: number | G38: KNOWN | H38: FIRST_EPSS | I38: 46242.25 | J38: 46243.433 | K38: HIGH | L38: Used as exploitation factor only when fresh and known.
A39: SYN-005 | B39: snapshot-20260809-000149 | C39: finding-8f31a6 | D39: EPSS_PERCENTILE | E39: 0.978 | F39: number | G39: KNOWN | H39: FIRST_EPSS | I39: 46242.25 | J39: 46243.433 | K39: HIGH | L39: Ranking/context only; never treated as probability.
A40: SYN-005 | B40: snapshot-20260809-000149 | C40: finding-8f31a6 | D40: KEV_STATUS | E40: TRUE | F40: boolean | G40: KNOWN | H40: CISA_KEV | I40: 46242.25 | J40: 46243.433 | K40: HIGH | L40: Known true or internal active exploitation creates mandatory remediation.
A41: SYN-005 | B41: snapshot-20260809-000149 | C41: finding-8f31a6 | D41: INTERNET_EXPOSURE | E41: TRUE | F41: boolean | G41: KNOWN | H41: WIZ_ASSET_GRAPH | I41: 46242.25 | J41: 46243.433 | K41: HIGH | L41: Contributes to exposure urgency.
...

Sheet Policy_Config
A1: VPAP 4.1 Synthetic Test Policy Configuration
A2: Example calibration policy for testing only. Production weights and thresholds require organizational approval and historical calibration.
A4: Priority threshold | B4: Minimum VPS | C4: Meaning | E4: Policy metadata | F4: Value
A5: P0 | B5: 80 | C5: Highest urgency | E5: Policy version | F5: 2026.07-pilot.1
A6: P1 | B6: 60 | C6: High urgency | E6: Synthetic data date | F6: 46243
A7: P2 | B7: 35 | C7: Moderate urgency
A8: P3 | B8: 0 | C8: Lower urgency | E8: Reference | F8: URL
E9: FIRST EPSS API | F9: https://api.first.org/data/v1/epss
A10: Exploitation component | B10: Points | C10: Threshold | D10: Condition | E10: CISA KEV catalog | F10: https://www.cisa.gov/known-exploited-vulnerabilities-catalog
A11: KEV or internal active exploitation | B11: 30 | D11: Mandatory remediation is true
A12: EPSS high | B12: 25 | C12: 0.9 | D12: EPSS probability >= 0.90
A13: EPSS elevated | B13: 20 | C13: 0.7 | D13: EPSS probability >= 0.70
A14: EPSS moderate | B14: 15 | C14: 0.3 | D14: EPSS probability >= 0.30
A15: EPSS low | B15: 10 | D15: EPSS probability < 0.30
A16: Exposure component | B16: Points | C16: Threshold | D16: Condition
A17: Internet and attack path true | B17: 20 | D17: Both are confirmed true
A18: One exposure indicator true | B18: 10 | D18: Either is confirmed true
A19: No exposure indicator true | B19: 0 | D19: Neither is confirmed true
A20: Technical impact component | B20: Points | C20: Threshold | D20: Condition
A21: Runtime not applicable | B21: 0 | D21: Vulnerable code path is not loaded
A22: High CVSS | B22: 20 | C22: 9 | D22: CVSS >= 9.0 and runtime applicable
A23: Medium CVSS | B23: 15 | C23: 7 | D23: CVSS >= 7.0 and runtime applicable
A24: Lower CVSS | B24: 10 | D24: CVSS < 7.0 and runtime applicable
A25: Business impact component | B25: Points | C25: Threshold | D25: Condition
A26: Critical | B26: 15 | D26: Critical business service
A27: High | B27: 10 | D27: High business service
A28: Medium | B28: 5 | D28: Medium business service
A29: Low | B29: 2 | D29: Low business service

Sheet Field_Guide
A1: Policy Engine Test Data Field Guide
A2: Use this sheet to interpret the synthetic input fields and formula-driven expected outputs.
A4: Field | B4: Type | C4: Example | D4: Where Used | E4: Processing Rule | F4: Output / Safety Note
A5: Finding_Instance_ID | B5: string | C5: finding-8f31a2 | D5: Trace and idempotency | E5: Identify one vulnerability on one asset. | F5: Never duplicate the same logical finding.
A6: CVE_ID | B6: string | C6: CVE-2026-99001 | D6: Evidence joins | E6: Validate CVE pattern and normalize casing. | F6: Links EPSS, KEV, and evidence records.
A7: Asset_ID | B7: string | C7: asset-payments-api-prod-01 | D7: Asset context | E7: Join to CMDB/Wiz context. | F7: Do not infer criticality from asset name alone.
A8: CVSS_Base_Score | B8: number | C8: 10 | D8: Severity component | E8: Validate 0-10. | F8: Never determines final priority alone.
A9: EPSS_Probability | B9: number | C9: 0.99999 | D9: Exploitation component | E9: Use only if status is KNOWN and fresh. | F9: Never convert ERROR/UNKNOWN to zero.
A10: EPSS_Percentile | B10: number | C10: 1 | D10: Ranking context | E10: Keep separate from probability. | F10: Not used as exploitation probability.
A11: KEV_Status | B11: boolean + status | C11: TRUE | D11: Mandatory remediation | E11: Known true or internal active exploitation sets mandatory flag. | F11: Unknown is not false.
A12: Internet_Exposure | B12: boolean + status | C12: TRUE | D12: Exposure component | E12: Combine with attack path reachability. | F12: Increases urgency when confirmed.
A13: Runtime_Applicability | B13: boolean + status | C13: TRUE | D13: Applicability gate | E13: Confirm vulnerable code path is loaded. | F13: False can reduce or remove technical impact.
A14: Attack_Path_Reachable | B14: boolean + status | C14: TRUE | D14: Exposure component | E14: Use confirmed routing/access evidence. | F14: Unknown can block final decision.
A15: Business_Criticality | B15: enum + status | C15: CRITICAL | D15: Business impact | E15: Use authoritative CMDB/business source. | F15: Never guess with AI.
A16: Compensating_Controls | B16: list | C16: WAF; egress restriction | D16: Mitigation context | E16: Record for review and potential policy adjustment. | F16: Does not erase mandatory remediation.
A17: Evidence_Snapshot_ID | B17: string | C17: snapshot-20260809-000145 | D17: Audit and replay | E17: Link decision to immutable evidence snapshot. | F17: Supports reproducibility.
A18: Policy_Version | B18: string | C18: 2026.07-pilot.1 | D18: Rulebook selection | E18: Load immutable rules, weights, and thresholds. | F18: Required to reproduce decisions.
A19: Quality_Check | B19: formula | C19: OK | D19: Quality gate | E19: Critical UNKNOWN/STALE/ERROR returns NEEDS_REVIEW. | F19: No fabricated defaults.
A20: Mandatory_Remediation | B20: formula boolean | C20: TRUE | D20: Policy obligation | E20: KEV known true OR internal active exploitation. | F20: Independent from operational priority.
A21: VPS | B21: formula number | C21: 100 | D21: Composite score | E21: Sum calibrated policy components. | F21: Only calculated when evidence quality is sufficient.
A22: Expected_Priority | B22: formula enum | C22: P0 | D22: Decision output | E22: Map VPS through policy thresholds. | F22: P0-P3 or REVIEW.
A23: Expected_Decision_Status | B23: formula enum | C23: FINAL | D23: Decision output | E23: FINAL when quality passes; otherwise NEEDS_REVIEW. | F23: Ticket lifecycle may separately be PROVISIONAL.
A24: Expected_Ticket_Action | B24: formula enum | C24: UPSERT_TICKET | D24: External workflow | E24: P0/P1/mandatory items are sent to ITSM. | F24: Transactional outbox prevents duplicates.

Sheet Summary
A1: VPAP 4.1 Synthetic Policy Engine Test Summary
A2: Formula-driven expected outcomes for the 20 synthetic test cases in Test_Cases.
A4: Metric | B4: Value | D4: Metric | E4: Value
A5: Total test cases | B5: =COUNTA(Test_Cases!$A$5:$A$24) -> 20 | D5: Expected FINAL | E5: =COUNTIF(Test_Cases!$AO$5:$AO$24,"FINAL") -> 16
A6: Expected P0 | B6: =COUNTIF(Test_Cases!$AN$5:$AN$24,"P0") -> 5 | D6: Expected NEEDS_REVIEW | E6: =COUNTIF(Test_Cases!$AO$5:$AO$24,"NEEDS_REVIEW") -> 4
A7: Expected P1 | B7: =COUNTIF(Test_Cases!$AN$5:$AN$24,"P1") -> 5 | D7: Expected mandatory remediation | E7: =SUMPRODUCT(--(Test_Cases!$AH$5:$AH$24=TRUE)) -> 5
